{
 "cells": [
  {
   "cell_type": "code",
   "execution_count": 16,
   "metadata": {},
   "outputs": [],
   "source": [
    "import mysql.connector as connector"
   ]
  },
  {
   "cell_type": "code",
   "execution_count": 17,
   "metadata": {},
   "outputs": [],
   "source": [
    "connection = connector.connect(host = \"localhost\", user = \"root\", password = \"root\", database = \"LittleLemonDB\")\n",
    "\n",
    "cursor = connection.cursor()"
   ]
  },
  {
   "cell_type": "code",
   "execution_count": 18,
   "metadata": {},
   "outputs": [
    {
     "name": "stdout",
     "output_type": "stream",
     "text": [
      "[('bookings',), ('customers',), ('menu',), ('menuitems',), ('orderdeliverystatus',), ('orders',), ('ordersview',)]\n"
     ]
    }
   ],
   "source": [
    "show_tables_query = \"SHOW tables;\"\n",
    "cursor.execute(show_tables_query)\n",
    "results = cursor.fetchall()\n",
    "print(results)\n"
   ]
  },
  {
   "cell_type": "code",
   "execution_count": 19,
   "metadata": {},
   "outputs": [
    {
     "name": "stdout",
     "output_type": "stream",
     "text": [
      "Unexpected exception formatting exception. Falling back to standard exception\n"
     ]
    },
    {
     "name": "stderr",
     "output_type": "stream",
     "text": [
      "Traceback (most recent call last):\n",
      "  File \"c:\\Users\\hayde\\AppData\\Local\\Programs\\Python\\Python310\\lib\\site-packages\\mysql\\connector\\connection_cext.py\", line 608, in cmd_query\n",
      "_mysql_connector.MySQLInterfaceError: You have an error in your SQL syntax; check the manual that corresponds to your MySQL server version for the right syntax to use near '\"\n",
      "    SELECT Customers.CustomerName\n",
      "        , Customers.ContactDetails\n",
      "    FROM ' at line 1\n",
      "\n",
      "The above exception was the direct cause of the following exception:\n",
      "\n",
      "Traceback (most recent call last):\n",
      "  File \"c:\\Users\\hayde\\AppData\\Local\\Programs\\Python\\Python310\\lib\\site-packages\\IPython\\core\\interactiveshell.py\", line 3378, in run_code\n",
      "    exec(code_obj, self.user_global_ns, self.user_ns)\n",
      "  File \"C:\\Users\\hayde\\AppData\\Local\\Temp\\ipykernel_11556\\4008252282.py\", line 9, in <module>\n",
      "    cursor.execute(select_query)\n",
      "  File \"c:\\Users\\hayde\\AppData\\Local\\Programs\\Python\\Python310\\lib\\site-packages\\mysql\\connector\\cursor_cext.py\", line 330, in execute\n",
      "  File \"c:\\Users\\hayde\\AppData\\Local\\Programs\\Python\\Python310\\lib\\site-packages\\mysql\\connector\\connection_cext.py\", line 616, in cmd_query\n",
      "mysql.connector.errors.ProgrammingError: 1064 (42000): You have an error in your SQL syntax; check the manual that corresponds to your MySQL server version for the right syntax to use near '\"\n",
      "    SELECT Customers.CustomerName\n",
      "        , Customers.ContactDetails\n",
      "    FROM ' at line 1\n",
      "\n",
      "During handling of the above exception, another exception occurred:\n",
      "\n",
      "Traceback (most recent call last):\n",
      "  File \"c:\\Users\\hayde\\AppData\\Local\\Programs\\Python\\Python310\\lib\\site-packages\\IPython\\core\\interactiveshell.py\", line 1997, in showtraceback\n",
      "    stb = self.InteractiveTB.structured_traceback(\n",
      "  File \"c:\\Users\\hayde\\AppData\\Local\\Programs\\Python\\Python310\\lib\\site-packages\\IPython\\core\\ultratb.py\", line 1112, in structured_traceback\n",
      "    return FormattedTB.structured_traceback(\n",
      "  File \"c:\\Users\\hayde\\AppData\\Local\\Programs\\Python\\Python310\\lib\\site-packages\\IPython\\core\\ultratb.py\", line 1006, in structured_traceback\n",
      "    return VerboseTB.structured_traceback(\n",
      "  File \"c:\\Users\\hayde\\AppData\\Local\\Programs\\Python\\Python310\\lib\\site-packages\\IPython\\core\\ultratb.py\", line 859, in structured_traceback\n",
      "    formatted_exception = self.format_exception_as_a_whole(etype, evalue, etb, number_of_lines_of_context,\n",
      "  File \"c:\\Users\\hayde\\AppData\\Local\\Programs\\Python\\Python310\\lib\\site-packages\\IPython\\core\\ultratb.py\", line 812, in format_exception_as_a_whole\n",
      "    frames.append(self.format_record(r))\n",
      "  File \"c:\\Users\\hayde\\AppData\\Local\\Programs\\Python\\Python310\\lib\\site-packages\\IPython\\core\\ultratb.py\", line 730, in format_record\n",
      "    result += ''.join(_format_traceback_lines(frame_info.lines, Colors, self.has_colors, lvals))\n",
      "  File \"c:\\Users\\hayde\\AppData\\Local\\Programs\\Python\\Python310\\lib\\site-packages\\stack_data\\utils.py\", line 145, in cached_property_wrapper\n",
      "    value = obj.__dict__[self.func.__name__] = self.func(obj)\n",
      "  File \"c:\\Users\\hayde\\AppData\\Local\\Programs\\Python\\Python310\\lib\\site-packages\\stack_data\\core.py\", line 734, in lines\n",
      "    pieces = self.included_pieces\n",
      "  File \"c:\\Users\\hayde\\AppData\\Local\\Programs\\Python\\Python310\\lib\\site-packages\\stack_data\\utils.py\", line 145, in cached_property_wrapper\n",
      "    value = obj.__dict__[self.func.__name__] = self.func(obj)\n",
      "  File \"c:\\Users\\hayde\\AppData\\Local\\Programs\\Python\\Python310\\lib\\site-packages\\stack_data\\core.py\", line 681, in included_pieces\n",
      "    pos = scope_pieces.index(self.executing_piece)\n",
      "  File \"c:\\Users\\hayde\\AppData\\Local\\Programs\\Python\\Python310\\lib\\site-packages\\stack_data\\utils.py\", line 145, in cached_property_wrapper\n",
      "    value = obj.__dict__[self.func.__name__] = self.func(obj)\n",
      "  File \"c:\\Users\\hayde\\AppData\\Local\\Programs\\Python\\Python310\\lib\\site-packages\\stack_data\\core.py\", line 660, in executing_piece\n",
      "    return only(\n",
      "  File \"c:\\Users\\hayde\\AppData\\Local\\Programs\\Python\\Python310\\lib\\site-packages\\executing\\executing.py\", line 164, in only\n",
      "    raise NotOneValueFound('Expected one value, found 0')\n",
      "executing.executing.NotOneValueFound: Expected one value, found 0\n"
     ]
    }
   ],
   "source": [
    "select_query = \"\"\"\"\n",
    "    SELECT Customers.CustomerName\n",
    "        , Customers.ContactDetails\n",
    "    FROM Orders\n",
    "        INNER JOIN Customers \n",
    "            ON Orders.CustomerID = Customers.CustomerID\n",
    "    WHERE Orders.TotalCost >= 60\n",
    "\"\"\"\n",
    "cursor.execute(select_query)\n",
    "results = cursor.fetchall()\n",
    "columns = cursor.column_names\n",
    "print(columns)\n",
    "for result in results:\n",
    "    print(result)"
   ]
  },
  {
   "cell_type": "code",
   "execution_count": 20,
   "metadata": {},
   "outputs": [],
   "source": [
    "connection.close()"
   ]
  }
 ],
 "metadata": {
  "kernelspec": {
   "display_name": "Python 3",
   "language": "python",
   "name": "python3"
  },
  "language_info": {
   "codemirror_mode": {
    "name": "ipython",
    "version": 3
   },
   "file_extension": ".py",
   "mimetype": "text/x-python",
   "name": "python",
   "nbconvert_exporter": "python",
   "pygments_lexer": "ipython3",
   "version": "3.10.11"
  }
 },
 "nbformat": 4,
 "nbformat_minor": 2
}
